Traceback (most recent call last):
  File "/Users/shannonburns/miniconda3/lib/python3.9/site-packages/jupyter_cache/executors/utils.py", line 51, in single_nb_execution
    executenb(
  File "/Users/shannonburns/miniconda3/lib/python3.9/site-packages/nbclient/client.py", line 1204, in execute
    return NotebookClient(nb=nb, resources=resources, km=km, **kwargs).execute()
  File "/Users/shannonburns/miniconda3/lib/python3.9/site-packages/nbclient/util.py", line 84, in wrapped
    return just_run(coro(*args, **kwargs))
  File "/Users/shannonburns/miniconda3/lib/python3.9/site-packages/nbclient/util.py", line 62, in just_run
    return loop.run_until_complete(coro)
  File "/Users/shannonburns/miniconda3/lib/python3.9/asyncio/base_events.py", line 647, in run_until_complete
    return future.result()
  File "/Users/shannonburns/miniconda3/lib/python3.9/site-packages/nbclient/client.py", line 663, in async_execute
    await self.async_execute_cell(
  File "/Users/shannonburns/miniconda3/lib/python3.9/site-packages/nbclient/client.py", line 965, in async_execute_cell
    await self._check_raise_for_error(cell, cell_index, exec_reply)
  File "/Users/shannonburns/miniconda3/lib/python3.9/site-packages/nbclient/client.py", line 862, in _check_raise_for_error
    raise CellExecutionError.from_cell_and_msg(cell, exec_reply_content)
nbclient.exceptions.CellExecutionError: An error occurred while executing the following cell:
------------------
#Finish the code below to make a density plot of Age in mindsetmatters
gf_dhistogram(#set formula here, #set dataframe here, #set bin and color options here)

------------------

Error in parse(text = x, srcfile = src): <text>:4:0: unexpected end of input
2: gf_dhistogram(#set formula here, #set dataframe here, #set bin and color options here)
3: 
  ^
Traceback:

ERROR: Error in parse(text = x, srcfile = src): <text>:4:0: unexpected end of input
2: gf_dhistogram(#set formula here, #set dataframe here, #set bin and color options here)
3: 
  ^


