Traceback (most recent call last):
  File "/Users/shannonburns/miniconda3/lib/python3.9/site-packages/jupyter_cache/executors/utils.py", line 51, in single_nb_execution
    executenb(
  File "/Users/shannonburns/miniconda3/lib/python3.9/site-packages/nbclient/client.py", line 1269, in execute
    return NotebookClient(nb=nb, resources=resources, km=km, **kwargs).execute()
  File "/Users/shannonburns/miniconda3/lib/python3.9/site-packages/nbclient/util.py", line 85, in wrapped
    return just_run(coro(*args, **kwargs))
  File "/Users/shannonburns/miniconda3/lib/python3.9/site-packages/nbclient/util.py", line 60, in just_run
    return loop.run_until_complete(coro)
  File "/Users/shannonburns/miniconda3/lib/python3.9/asyncio/base_events.py", line 647, in run_until_complete
    return future.result()
  File "/Users/shannonburns/miniconda3/lib/python3.9/site-packages/nbclient/client.py", line 707, in async_execute
    await self.async_execute_cell(
  File "/Users/shannonburns/miniconda3/lib/python3.9/site-packages/nbclient/client.py", line 1025, in async_execute_cell
    await self._check_raise_for_error(cell, cell_index, exec_reply)
  File "/Users/shannonburns/miniconda3/lib/python3.9/site-packages/nbclient/client.py", line 919, in _check_raise_for_error
    raise CellExecutionError.from_cell_and_msg(cell, exec_reply_content)
nbclient.exceptions.CellExecutionError: An error occurred while executing the following cell:
------------------
x1 <- c(1,2,3,4,5)
x2 <- c(18,21,20,23)
data.frame(x1=x1, x2=x2)
------------------

Error in data.frame(x1 = x1, x2 = x2): arguments imply differing number of rows: 5, 4
Traceback:

1. data.frame(x1 = x1, x2 = x2)
2. stop(gettextf("arguments imply differing number of rows: %s", 
 .     paste(unique(nrows), collapse = ", ")), domain = NA)
ERROR: Error in data.frame(x1 = x1, x2 = x2): arguments imply differing number of rows: 5, 4


